Workbook
Name a: #REF!
Name abc: #REF!
Name acd: 'Masse & Centrage'!$E$59
Name b: #REF!
Name bagages: 'Masse & Centrage'!$E$58
Name bagages: '[1]Masse & Centrage'!$F$71
Name bagages: #REF!
Name brasCG: 'Masse & Centrage'!$D$46
Name brasCG: '[1]Masse & Centrage'!$E$57
Name brasCG: #REF!
Name central: 'Masse & Centrage'!$E$59
Name central: '[1]Masse & Centrage'!$F$72
Name central: #REF!
Name conso75: 'Masse & Centrage'!$D$64
Name conso75: '[1]Masse & Centrage'!$E$76
Name conso75: #REF!
Name daqz: #REF!
Name erty: 'Masse & Centrage'!$E$55
Name immat: 'Masse & Centrage'!$D$44
Name immat: '[1]Masse & Centrage'!$E$55
Name immat: #REF!
Name inutiles: 'Masse & Centrage'!$D$61
Name inutiles: '[1]Masse & Centrage'!$E$73
Name inutiles: #REF!
Name massevide: 'Masse & Centrage'!$E$46
Name massevide: '[1]Masse & Centrage'!$F$57
Name massevide: #REF!
Name nouveau: #REF!
Name perfo1terrain: #REF!
Name perfo1terrain: #REF!
Name perfo1terrain: #REF!
Name Perfost: #REF!
Name poidsmax: 'Masse & Centrage'!$E$55
Name poidsmax: '[1]Masse & Centrage'!$F$68
Name poidsmax: #REF!
Name Résume2: #REF!
Name temp12: #REF!
Name temp12: 'MdV DR221 Perfos'!#REF!
Name temp12: 'Perfos Dégagement'!#REF!
Name temp12: 'Perfos Départ'!#REF!
Name temp12: 'Perfos Destination'!#REF!
Name temp12: Résumé!#REF!
Name temp12: #REF!
Name temp13: #REF!
Name temp14: #REF!
Name temp14: #REF!
Name temp14: #REF!
Name temp14: #REF!
Name temp15: #REF!
Name temp15: #REF!
Name temp15: #REF!
Name type: 'Masse & Centrage'!$D$43
Name type: '[1]Masse & Centrage'!$E$54
Name type: #REF!

Sheet Masse & Centrage
B1: ="Masse & Centrage "&type&" / "&immat -> Masse & Centrage DR221 / F-BPCT
B2: ="Masse maxi "&poidsmax&" kg"&IF(bagages<>0," dont bagages "&bagages&" kg maxi","") -> Masse maxi 840 kg | E2: Date de pesée : | F2: =D45 -> 43670
B3: Attention, seuls les documents d'origine font foi
C4: Litres | D4: Masse (kg) | E4: Bras de levier (mm) | F4: Moment (mm.kg)
B5: Avion vide (1) | D5: =massevide -> 521.3 | E5: =+brasCG -> 0.33 | F5: =IF(D5<>"",E5*D5,"") -> 172.029
B6: CdB | D6: 70 | E6: =+D56 -> 0.43 | F6: =IF(D6<>"",E6*D6,"") -> 30.1
B7: Copilote | D7: 80 | E7: =+D56 -> 0.43 | F7: =IF(D7<>"",E7*D7,"") -> 34.4
B8: Passagers AR | D8: 3 | E8: =+D57 -> 1.22 | F8: =IF(D8<>"",E8*D8,"") -> 3.66
B9: ="Bagages "&E58&" kg maxi" -> Bagages 0 kg maxi | D9: 10 | E9: =+D58 -> 1.22 | F9: =IF(D9<>"",E9*D9,"") -> 12.2
B10: ="Essence "&E59&" litres maxi" -> Essence 110 litres maxi | C10: 110 | D10: =C10*D60 -> 79.2 | E10: =D59 -> 1.12 | F10: =IF(D10<>"",E10*D10,"") -> 88.704
B11: Autonomie : | C11: =MAX((C10-inutiles)/C12/24,0) -> 0.18333333 | E11: =IF(C10>central,central&" litres maxi",IF(D10<inutiles,inutiles&" litres mini",""))
B12: Conso 75% | C12: =VLOOKUP(B12,C64:E65,2,FALSE) -> 25
B13: Total départ | D13: =SUM(D5:D10) -> 763.5 | E13: =F13/D13 -> 0.44674918 | F13: =SUM(F5:F10) -> 341.093
B14: Délestage essence | C14: 40 | D14: =-D60*C14 -> -28.8 | E14: =E10 -> 1.12 | F14: =IF(D14<>"",E14*D14,"") -> -32.256
B15: Carburant à l'arrivée : | C15: =MAX((C10-C14-inutiles)/C12/24,0) -> 0.11666667 | D15: =IF(D14>D10-inutiles,"Délestage excessif, maxi = "&C10-inutiles&" litres","")
B16: Total arrivée | D16: =D13+D14 -> 734.7 | E16: =F16/D16 -> 0.42035797 | F16: =F13+F14 -> 308.837
B17: (1) L'avion "vide" ne contient que ses instruments et son huile, pas d'essence.
A38: Pour éviter la destruction des formules, cette feuille est protégée. Pour enlever cette protection faire : "Révision" et "Ôter la protection de la feuille"
C40: Zone de travail ; ne pas toucher
D42: Bras de levier | E42: Masse
C43: Avion type | D43: DR221
C44: Avion immat | D44: F-BPCT
C45: date pesée | D45: 43670
C46: Masse à vide (CG) | D46: 0.33 | E46: 521.3
C47: Graphe AV bas | D47: 0.31 | E47: 440
C48: Graphe AV bas | D48: 0.31 | E48: 600
C49: Graphe AV haut | D49: 0.473 | E49: 840
C50: Graphe AR haut | D50: 0.59 | E50: 840
C51: Graphe AR bas | D51: 0.59 | E51: =E47 -> 440
C52: Cent Réel Dep | D52: =F13/D13 -> 0.44674918 | E52: =D13 -> 763.5
C53: Cent Réel Arr | D53: =F16/D16 -> 0.42035797 | E53: =D16 -> 734.7
C54: Cent Réel 0 | D54: =(F13-F10)/E54 -> 0.368828 | E54: =+D13-D10 -> 684.3
C55: Poids max | E55: 840
C56: Passagers AV | D56: 0.43
C57: Passagers AR | D57: 1.22
C58: Bagages max | D58: 1.22 | E58: 0
C59: Réservoir central | D59: 1.12 | E59: 110
C60: Densité | D60: 0.72
C61: inutilisables | D61: 0
C62: Réservoirs aile | D62: 0
...

Sheet Perfos Départ
B1: ="Performances "&'Masse & Centrage'!D43&" / "&'Masse & Centrage'!D44 -> Performances DR221 / F-BPCT | H1: Terrain de départ
H2: LFPN
C5: QNH local | E5: 1025 | F5: hPa | G5: } | H5: Altitude-pression selon le QNH local
H6: =E7-(E5-1013)*28 -> 202 | I6: =ROUND(H6/3.28084,0) -> 62 | J6: =IF(I6<1501,"",H6) | L6: =IF(I6<1501,"",I6)
C7: Altitude terrain | E7: 538 | F7: ft | H7: =IF(I6<1501,H6,"altitude max MdV = 1500 m") -> 202
K8: Altitude densité = | L8: =I42+120*(E9-(15-2*I42/1000)) -> 1330.48
C9: Température | E9: 24 | F9: ° C | G9: =ROUND(E9-15+M34*2/1000,0) -> 9
C11: Vent (de face) | E11: 9 | F11: kt | G11: → | H11: pour une composante arrière mettre un —
C13: Masse | E13: ='Masse & Centrage'!D13 -> 763.5 | F13: kg | H13: =IF(E13<='Masse & Centrage'!E55," ","masse max = "&'Masse & Centrage'!E55&" kg")
C16: Performances de DECOLLAGE
C18: Piste en dur - passage des 15 m - avec majoration Alcyons de 15 %
F19: Distance de décollage = | G19: =L69 -> 418.0238 | N19: elle doit être < TODA
C21: Piste en herbe - passage des 15 m - avec majoration Alcyons de 15 %
F22: Distance de décollage = | G22: =L72 -> 503.05754 | N22: elle doit être < TODA
C25: Performances d'ATTERRISSAGE * (retour immédiat)
C27: Piste en dur ou en herbe - passage des 15 m - avec majoration Alcyons de 15 %
F28: Distance d'atterrissage = | G28: =L153 -> 514.866 | L28: elle doit être < LDA
F29: sans volet (+ 50 %) = | G29: =L154 -> 580.26
B32: * | C32: Le tableau de performance d'atterrissage du Manuel de Vol du DR221 ne propose qu'un seul
C33: paramètre : la masse à l'atterrissage (donc ni altitude, ni température)
C34: Le résultat de ce tableau de performance est la distance de roulement
C35: Les distances de roulement sont augmentées de 15% ou 50% sans volet (majorations Alcyons), puis
C36: augmentées de 300 m (distance forfaitaire Alcyons du passage des 15 mètres jusqu'à la zone de posé)
B38: Performances de décollage du Robin DR221 / F-BOZU
C40: QNH local | F40: =E5 -> 1025 | G40: hPa | H40: } | I40: Altitude-pression selon le QNH local
I41: =F42-(F40-1013)*28 -> 202 | J41: =ROUND(I41/3.28084,0) -> 62 | K41: =IF(J41<1501,"",I41) | M41: =IF(J41<1501,"",J41)
C42: Altitude du terrain (VAC) | F42: =E7 -> 538 | G42: ft | I42: =IF(J41<1501,I41,"altitude max du manuel de vol = 1500 m") -> 202 | N42: =F42-(F40-1013)*28 -> 202
C44: Altitude- | E44: Température | G44: Masse 840 Kg | K44: Masse 640 kg
C45: pression en ft | G45: Piste Béton | I45: Piste Herbe | K45: Piste Béton | M45: Piste Herbe
F46: 0 | G46: =IF($C$47<=$C$86,G80+($C$47-$C$82)*(G84-G80)/($C$86-$C$82),IF($C$47<=$C$90,G84+($C$47-$C$86)*(G88-G84)/($C$90-$C$86),G88+($C$47-$C$90)*(G92-G88)/($C$94-$C$90))) -> 446.15703 | H46: =G46*60/100 -> 267.69422 | I46: =IF($C$47<=$C$86,I80+($C$47-$C$82)*(I84-I80)/($C$86-$C$82),IF($C$47<=$C$90,I84+($C$47-$C$86)*(I88-I84)/($C$90-$C$86),I88+($C$47-$C$90)*(I92-I88)/($C$94-$C$90))) -> 529.85126 | J46: =I46*70/100 -> 370.89588 | K46: =IF($C$47<=$C$86,K80+($C$47-$C$82)*(K84-K80)/($C$86-$C$82),IF($C$47<=$C$90,K84+($C$47-$C$86)*(K88-K84)/($C$90-$C$86),K88+($C$47-$C$90)*(K92-K88)/($C$94-$C$90))) -> 265.27206 | L46: =K46*60/100 -> 159.16324 | M46: =IF($C$47<=$C$86,M80+($C$47-$C$82)*(M84-M80)/($C$86-$C$82),IF($C$47<=$C$90,M84+($C$47-$C$86)*(M88-M84)/($C$90-$C$86),M88+($C$47-$C$90)*(M92-M88)/($C$94-$C$90))) -> 315.03422 | N46: =M46*70/100 -> 220.52395
C47: =IF(J41<1501,IF(F61<841,I41,"#####"),"#####") -> 202 | F47: 15 | G47: =IF($C$47<=$C$86,G81+($C$47-$C$82)*(G85-G81)/($C$86-$C$82),IF($C$47<=$C$90,G85+($C$47-$C$86)*(G89-G85)/($C$90-$C$86),G89+($C$47-$C$90)*(G93-G89)/($C$94-$C$90))) -> 478.61985 | H47: =G47*60/100 -> 287.17191 | I47: =IF($C$47<=$C$86,I81+($C$47-$C$82)*(I85-I81)/($C$86-$C$82),IF($C$47<=$C$90,I85+($C$47-$C$86)*(I89-I85)/($C$90-$C$86),I89+($C$47-$C$90)*(I93-I89)/($C$94-$C$90))) -> 572.31407 | J47: =I47*70/100 -> 400.61985 | K47: =IF($C$47<=$C$86,K81+($C$47-$C$82)*(K85-K81)/($C$86-$C$82),IF($C$47<=$C$90,K85+($C$47-$C$86)*(K89-K85)/($C$90-$C$86),K89+($C$47-$C$90)*(K93-K89)/($C$94-$C$90))) -> 284.57351 | L47: =K47*60/100 -> 170.74411 | M47: =IF($C$47<=$C$86,M81+($C$47-$C$82)*(M85-M81)/($C$86-$C$82),IF($C$47<=$C$90,M85+($C$47-$C$86)*(M89-M85)/($C$90-$C$86),M89+($C$47-$C$90)*(M93-M89)/($C$94-$C$90))) -> 340.28138 | N47: =M47*70/100 -> 238.19697
F48: 30 | G48: =IF($C$47<=$C$86,G82+($C$47-$C$82)*(G86-G82)/($C$86-$C$82),IF($C$47<=$C$90,G86+($C$47-$C$86)*(G90-G86)/($C$90-$C$86),G90+($C$47-$C$90)*(G94-G90)/($C$94-$C$90))) -> 509.85126 | H48: =G48*60/100 -> 305.91075 | I48: =IF($C$47<=$C$86,I82+($C$47-$C$82)*(I86-I82)/($C$86-$C$82),IF($C$47<=$C$90,I86+($C$47-$C$86)*(I90-I86)/($C$90-$C$86),I90+($C$47-$C$90)*(I94-I90)/($C$94-$C$90))) -> 616.00829 | J48: =I48*70/100 -> 431.2058 | K48: =IF($C$47<=$C$86,K82+($C$47-$C$82)*(K86-K82)/($C$86-$C$82),IF($C$47<=$C$90,K86+($C$47-$C$86)*(K90-K86)/($C$90-$C$86),K90+($C$47-$C$90)*(K94-K90)/($C$94-$C$90))) -> 303.1428 | L48: =K48*60/100 -> 181.88568 | M48: =IF($C$47<=$C$86,M82+($C$47-$C$82)*(M86-M82)/($C$86-$C$82),IF($C$47<=$C$90,M86+($C$47-$C$86)*(M90-M86)/($C$90-$C$86),M90+($C$47-$C$90)*(M94-M90)/($C$94-$C$90))) -> 366.2607 | N48: =M48*70/100 -> 256.38249
F49: 45 | G49: =IF($C$47<=$C$86,G83+($C$47-$C$82)*(G87-G83)/($C$86-$C$82),IF($C$47<=$C$90,G87+($C$47-$C$86)*(G91-G87)/($C$90-$C$86),G91+($C$47-$C$90)*(G95-G91)/($C$94-$C$90))) -> 551.08266 | H49: =G49*60/100 -> 330.6496 | I49: =IF($C$47<=$C$86,I83+($C$47-$C$82)*(I87-I83)/($C$86-$C$82),IF($C$47<=$C$90,I87+($C$47-$C$86)*(I91-I87)/($C$90-$C$86),I91+($C$47-$C$90)*(I95-I91)/($C$94-$C$90))) -> 677.2397 | J49: =I49*70/100 -> 474.06779 | K49: =IF($C$47<=$C$86,K83+($C$47-$C$82)*(K87-K83)/($C$86-$C$82),IF($C$47<=$C$90,K87+($C$47-$C$86)*(K91-K87)/($C$90-$C$86),K91+($C$47-$C$90)*(K95-K91)/($C$94-$C$90))) -> 327.6578 | L49: =K49*60/100 -> 196.59468 | M49: =IF($C$47<=$C$86,M83+($C$47-$C$82)*(M87-M83)/($C$86-$C$82),IF($C$47<=$C$90,M87+($C$47-$C$86)*(M91-M87)/($C$90-$C$86),M91+($C$47-$C$90)*(M95-M91)/($C$94-$C$90))) -> 402.66712 | N49: =M49*70/100 -> 281.86699
C51: Température | F51: =E9 -> 24 | G51: °C
F53: =IF(F51<46,F51,"#####") -> 24 | G53: =IF($F$53<$F$47,G46+($F$53-$F$46)*(G47-G46)/($F$47-$F$46),IF($F$53<$F$48,G47+($F$53-$F$47)*(G48-G47)/($F$48-$F$47),G48+($F$53-$F$48)*(G49-G48)/($F$49-$F$48))) -> 497.35869 | H53: =G53*60/100 -> 298.41522 | I53: =IF($F$53<$F$47,I46+($F$53-$F$46)*(I47-I46)/($F$47-$F$46),IF($F$53<$F$48,I47+($F$53-$F$47)*(I48-I47)/($F$48-$F$47),I48+($F$53-$F$48)*(I49-I48)/($F$49-$F$48))) -> 598.5306 | J53: =I53*70/100 -> 418.97142 | K53: =IF($F$53<$F$47,K46+($F$53-$F$46)*(K47-K46)/($F$47-$F$46),IF($F$53<$F$48,K47+($F$53-$F$47)*(K48-K47)/($F$48-$F$47),K48+($F$53-$F$48)*(K49-K48)/($F$49-$F$48))) -> 295.71508 | L53: =K53*60/100 -> 177.42905 | M53: =IF($F$53<$F$47,M46+($F$53-$F$46)*(M47-M46)/($F$47-$F$46),IF($F$53<$F$48,M47+($F$53-$F$47)*(M48-M47)/($F$48-$F$47),M48+($F$53-$F$48)*(M49-M48)/($F$49-$F$48))) -> 355.86897 | N53: =M53*70/100 -> 249.10828
C55: Vent (composante de face) | F55: =E11 -> 9 | G55: kt | H55: → | I55: pour une composante arrière mettre un —
C57: coefficient vent : | F57: =IF(F55>=0,IF(F55<G98,1+(F55)*(J98-1)/(G98-0),IF(F55<G99,J98+(F55-G98)*(J99-J98)/(G99-G98),J99+(F55-G99)*(J100-J99)/(G100-G99))),1+0.1*IF(INT(-F55/2)<>-F55/2,INT(-F55/2+1),INT(-F55/2))) -> 0.865 | J57: Masse | K57: =F61 -> 763.5 | L57: kg
I58: Piste Béton | K58: Piste Herbe
I59: =I65*F57 -> 363.49896 | J59: =J65*F57 -> 218.09938 | K59: =K65*F57 -> 437.44134 | L59: =L65*F57 -> 306.20894
C61: Masse | F61: =E13 -> 763.5 | G61: kg | I61: =IF(F61<=840," ","masse maximale 840 kg dépassée")
...

Sheet Perfos Destination
B1: ="Performances "&'Masse & Centrage'!D43&" / "&'Masse & Centrage'!D44 -> Performances DR221 / F-BPCT | H1: Terrain de destination
H2: LFPZ
C5: QNH local | E5: 1025 | F5: hPa | G5: } | H5: Altitude-pression selon le QNH local
H6: =E7-(E5-1013)*28 -> 36 | I6: =ROUND(H6/3.28084,0) -> 11 | J6: =IF(I6<1501,"",H6) | L6: =IF(I6<1501,"",I6)
C7: Altitude terrain | E7: 372 | F7: ft | H7: =IF(I6<1501,H6,"altitude max MdV = 1500 m") -> 36
K8: Altitude densité = | L8: =I42+120*(E9-(15-2*I42/1000)) -> 1124.64
C9: Température | E9: 24 | F9: ° C | G9: =ROUND(E9-15+M34*2/1000,0) -> 9
C11: Vent (de face) | E11: 7 | F11: kt | G11: → | H11: pour une composante arrière mettre un —
C13: Masse | E13: ='Masse & Centrage'!D16 -> 734.7 | F13: kg | H13: =IF(E13<='Masse & Centrage'!E55," ","masse max = "&'Masse & Centrage'!E55&" kg")
C16: Performances d'ATTERRISSAGE *
C18: Piste en dur ou en herbe - passage des 15 m - avec majoration Alcyons de 15 %
F19: Distance d'atterrissage = | G19: =L153 -> 509.1436 | L19: elle doit être < LDA
F20: sans volet (+ 50 %) = | G20: =L154 -> 572.796
C23: Performances de DECOLLAGE (retour immédiat)
C25: Piste en dur - passage des 15 m - avec majoration Alcyons de 15 %
F26: Distance de décollage = | G26: =L69 -> 396.40966 | N26: elle doit être < TODA
C28: Piste en herbe - passage des 15 m - avec majoration Alcyons de 15 %
F29: Distance de décollage = | G29: =L72 -> 474.87245 | N29: elle doit être < TODA
B32: * | C32: Le tableau de performance d'atterrissage du Manuel de Vol du DR221 ne propose qu'un seul
C33: paramètre : la masse à l'atterrissage (donc ni altitude, ni température)
C34: Le résultat de ce tableau de performance est la distance de roulement
C35: Les distances de roulement sont augmentées de 15% ou 50% sans volet (majorations Alcyons), puis
C36: augmentées de 300 m (distance forfaitaire Alcyons du passage des 15 mètres jusqu'à la zone de posé)
B38: Performances de décollage du Robin DR221 / F-BOZU
C40: QNH local | F40: =E5 -> 1025 | G40: hPa | H40: } | I40: Altitude-pression selon le QNH local
I41: =F42-(F40-1013)*28 -> 36 | J41: =ROUND(I41/3.28084,0) -> 11 | K41: =IF(J41<1501,"",I41) | M41: =IF(J41<1501,"",J41)
C42: Altitude du terrain (VAC) | F42: =E7 -> 372 | G42: ft | I42: =IF(J41<1501,I41,"altitude max du manuel de vol = 1500 m") -> 36 | N42: =F42-(F40-1013)*28 -> 36
C44: Altitude- | E44: Température | G44: Masse 840 Kg | K44: Masse 640 kg
C45: pression en ft | G45: Piste Béton | I45: Piste Herbe | K45: Piste Béton | M45: Piste Herbe
F46: 0 | G46: =IF($C$47<=$C$86,G80+($C$47-$C$82)*(G84-G80)/($C$86-$C$82),IF($C$47<=$C$90,G84+($C$47-$C$86)*(G88-G84)/($C$90-$C$86),G88+($C$47-$C$90)*(G92-G88)/($C$94-$C$90))) -> 441.09729 | H46: =G46*60/100 -> 264.65838 | I46: =IF($C$47<=$C$86,I80+($C$47-$C$82)*(I84-I80)/($C$86-$C$82),IF($C$47<=$C$90,I84+($C$47-$C$86)*(I88-I84)/($C$90-$C$86),I88+($C$47-$C$90)*(I92-I88)/($C$94-$C$90))) -> 521.75567 | J46: =I46*70/100 -> 365.22897 | K46: =IF($C$47<=$C$86,K80+($C$47-$C$82)*(K84-K80)/($C$86-$C$82),IF($C$47<=$C$90,K84+($C$47-$C$86)*(K88-K84)/($C$90-$C$86),K88+($C$47-$C$90)*(K92-K88)/($C$94-$C$90))) -> 262.26368 | L46: =K46*60/100 -> 157.35821 | M46: =IF($C$47<=$C$86,M80+($C$47-$C$82)*(M84-M80)/($C$86-$C$82),IF($C$47<=$C$90,M84+($C$47-$C$86)*(M88-M84)/($C$90-$C$86),M88+($C$47-$C$90)*(M92-M88)/($C$94-$C$90))) -> 310.22082 | N46: =M46*70/100 -> 217.15457
C47: =IF(J41<1501,IF(F61<841,I41,"#####"),"#####") -> 36 | F47: 15 | G47: =IF($C$47<=$C$86,G81+($C$47-$C$82)*(G85-G81)/($C$86-$C$82),IF($C$47<=$C$90,G85+($C$47-$C$86)*(G89-G85)/($C$90-$C$86),G89+($C$47-$C$90)*(G93-G89)/($C$94-$C$90))) -> 471.53621 | H47: =G47*60/100 -> 282.92173 | I47: =IF($C$47<=$C$86,I81+($C$47-$C$82)*(I85-I81)/($C$86-$C$82),IF($C$47<=$C$90,I85+($C$47-$C$86)*(I89-I85)/($C$90-$C$86),I89+($C$47-$C$90)*(I93-I89)/($C$94-$C$90))) -> 562.19459 | J47: =I47*70/100 -> 393.53621 | K47: =IF($C$47<=$C$86,K81+($C$47-$C$82)*(K85-K81)/($C$86-$C$82),IF($C$47<=$C$90,K85+($C$47-$C$86)*(K89-K85)/($C$90-$C$86),K89+($C$47-$C$90)*(K93-K89)/($C$94-$C$90))) -> 280.36178 | L47: =K47*60/100 -> 168.21707 | M47: =IF($C$47<=$C$86,M81+($C$47-$C$82)*(M85-M81)/($C$86-$C$82),IF($C$47<=$C$90,M85+($C$47-$C$86)*(M89-M85)/($C$90-$C$86),M89+($C$47-$C$90)*(M93-M89)/($C$94-$C$90))) -> 334.26463 | N47: =M47*70/100 -> 233.98524
F48: 30 | G48: =IF($C$47<=$C$86,G82+($C$47-$C$82)*(G86-G82)/($C$86-$C$82),IF($C$47<=$C$90,G86+($C$47-$C$86)*(G90-G86)/($C$90-$C$86),G90+($C$47-$C$90)*(G94-G90)/($C$94-$C$90))) -> 501.75567 | H48: =G48*60/100 -> 301.0534 | I48: =IF($C$47<=$C$86,I82+($C$47-$C$82)*(I86-I82)/($C$86-$C$82),IF($C$47<=$C$90,I86+($C$47-$C$86)*(I90-I86)/($C$90-$C$86),I90+($C$47-$C$90)*(I94-I90)/($C$94-$C$90))) -> 602.85296 | J48: =I48*70/100 -> 421.99707 | K48: =IF($C$47<=$C$86,K82+($C$47-$C$82)*(K86-K82)/($C$86-$C$82),IF($C$47<=$C$90,K86+($C$47-$C$86)*(K90-K86)/($C$90-$C$86),K90+($C$47-$C$90)*(K94-K90)/($C$94-$C$90))) -> 298.3294 | L48: =K48*60/100 -> 178.99764 | M48: =IF($C$47<=$C$86,M82+($C$47-$C$82)*(M86-M82)/($C$86-$C$82),IF($C$47<=$C$90,M86+($C$47-$C$86)*(M90-M86)/($C$90-$C$86),M90+($C$47-$C$90)*(M94-M90)/($C$94-$C$90))) -> 358.43892 | N48: =M48*70/100 -> 250.90725
F49: 45 | G49: =IF($C$47<=$C$86,G83+($C$47-$C$82)*(G87-G83)/($C$86-$C$82),IF($C$47<=$C$90,G87+($C$47-$C$86)*(G91-G87)/($C$90-$C$86),G91+($C$47-$C$90)*(G95-G91)/($C$94-$C$90))) -> 541.97513 | H49: =G49*60/100 -> 325.18508 | I49: =IF($C$47<=$C$86,I83+($C$47-$C$82)*(I87-I83)/($C$86-$C$82),IF($C$47<=$C$90,I87+($C$47-$C$86)*(I91-I87)/($C$90-$C$86),I91+($C$47-$C$90)*(I95-I91)/($C$94-$C$90))) -> 663.07242 | J49: =I49*70/100 -> 464.15069 | K49: =IF($C$47<=$C$86,K83+($C$47-$C$82)*(K87-K83)/($C$86-$C$82),IF($C$47<=$C$90,K87+($C$47-$C$86)*(K91-K87)/($C$90-$C$86),K91+($C$47-$C$90)*(K95-K91)/($C$94-$C$90))) -> 322.24272 | L49: =K49*60/100 -> 193.34563 | M49: =IF($C$47<=$C$86,M83+($C$47-$C$82)*(M87-M83)/($C$86-$C$82),IF($C$47<=$C$90,M87+($C$47-$C$86)*(M91-M87)/($C$90-$C$86),M91+($C$47-$C$90)*(M95-M91)/($C$94-$C$90))) -> 394.24367 | N49: =M49*70/100 -> 275.97057
C51: Température | F51: =E9 -> 24 | G51: °C
F53: =IF(F51<46,F51,"#####") -> 24 | G53: =IF($F$53<$F$47,G46+($F$53-$F$46)*(G47-G46)/($F$47-$F$46),IF($F$53<$F$48,G47+($F$53-$F$47)*(G48-G47)/($F$48-$F$47),G48+($F$53-$F$48)*(G49-G48)/($F$49-$F$48))) -> 489.66789 | H53: =G53*60/100 -> 293.80073 | I53: =IF($F$53<$F$47,I46+($F$53-$F$46)*(I47-I46)/($F$47-$F$46),IF($F$53<$F$48,I47+($F$53-$F$47)*(I48-I47)/($F$48-$F$47),I48+($F$53-$F$48)*(I49-I48)/($F$49-$F$48))) -> 586.58961 | J53: =I53*70/100 -> 410.61273 | K53: =IF($F$53<$F$47,K46+($F$53-$F$46)*(K47-K46)/($F$47-$F$46),IF($F$53<$F$48,K47+($F$53-$F$47)*(K48-K47)/($F$48-$F$47),K48+($F$53-$F$48)*(K49-K48)/($F$49-$F$48))) -> 291.14235 | L53: =K53*60/100 -> 174.68541 | M53: =IF($F$53<$F$47,M46+($F$53-$F$46)*(M47-M46)/($F$47-$F$46),IF($F$53<$F$48,M47+($F$53-$F$47)*(M48-M47)/($F$48-$F$47),M48+($F$53-$F$48)*(M49-M48)/($F$49-$F$48))) -> 348.7692 | N53: =M53*70/100 -> 244.13844
C55: Vent (composante de face) | F55: =E11 -> 7 | G55: kt | H55: → | I55: pour une composante arrière mettre un —
C57: coefficient vent : | F57: =IF(F55>=0,IF(F55<G98,1+(F55)*(J98-1)/(G98-0),IF(F55<G99,J98+(F55-G98)*(J99-J98)/(G99-G98),J99+(F55-G99)*(J100-J99)/(G100-G99))),1+0.1*IF(INT(-F55/2)<>-F55/2,INT(-F55/2+1),INT(-F55/2))) -> 0.895 | J57: Masse | K57: =F61 -> 734.7 | L57: kg
I58: Piste Béton | K58: Piste Herbe
I59: =I65*F57 -> 344.70405 | J59: =J65*F57 -> 206.82243 | K59: =K65*F57 -> 412.93257 | L59: =L65*F57 -> 289.0528
C61: Masse | F61: =E13 -> 734.7 | G61: kg | I61: =IF(F61<=840," ","masse maximale 840 kg dépassée")
...

Sheet Perfos Dégagement
B1: ="Performances "&'Masse & Centrage'!D43&" / "&'Masse & Centrage'!D44 -> Performances DR221 / F-BPCT | H1: Terrain de dégagement
C5: QNH local | E5: 1013 | F5: hPa | G5: } | H5: Altitude-pression selon le QNH local
H6: =E7-(E5-1013)*28 -> 0 | I6: =ROUND(H6/3.28084,0) -> 0 | J6: =IF(I6<1501,"",H6) | L6: =IF(I6<1501,"",I6)
C7: Altitude terrain | F7: ft | H7: =IF(I6<1501,H6,"altitude max MdV = 1500 m") -> 0
K8: Altitude densité = | L8: =I42+120*(E9-(15-2*I42/1000)) -> -1800
C9: Température | F9: ° C | G9: =ROUND(E9-15+M34*2/1000,0) -> -15
C11: Vent (de face) | F11: kt | G11: → | H11: pour une composante arrière mettre un —
C13: Masse | E13: ='Masse & Centrage'!D16 -> 734.7 | F13: kg | H13: =IF(E13<='Masse & Centrage'!E55," ","masse max = "&'Masse & Centrage'!E55&" kg")
C16: Performances d'ATTERRISSAGE *
C18: Piste en dur ou en herbe - passage des 15 m - avec majoration Alcyons de 15 %
F19: Distance d'atterrissage = | G19: =L153 -> 438.57224 | L19: elle doit être < LDA
F20: sans volet (+ 50 %) = | G20: =L154 -> 480.7464
C23: Performances de DECOLLAGE (départ immédiat)
C25: Piste en dur - passage des 15 m - avec majoration Alcyons de 15 %
F26: Distance de décollage = | G26: =L69 -> 397.99008 | N26: elle doit être < TODA
C28: Piste en herbe - passage des 15 m - avec majoration Alcyons de 15 %
F29: Distance de décollage = | G29: =L72 -> 470.35191 | N29: elle doit être < TODA
B32: * | C32: Le tableau de performance d'atterrissage du Manuel de Vol du DR221 ne propose qu'un seul
C33: paramètre : la masse à l'atterrissage (donc ni altitude, ni température)
C34: Le résultat de ce tableau de performance est la distance de roulement
C35: Les distances de roulement sont augmentées de 15% ou 50% sans volet (majorations Alcyons), puis
C36: augmentées de 300 m (distance forfaitaire Alcyons du passage des 15 mètres jusqu'à la zone de posé)
B38: Performances de décollage du Robin DR221 / F-BOZU
C40: QNH local | F40: =E5 -> 1013 | G40: hPa | H40: } | I40: Altitude-pression selon le QNH local
I41: =F42-(F40-1013)*28 -> 0 | J41: =ROUND(I41/3.28084,0) -> 0 | K41: =IF(J41<1501,"",I41) | M41: =IF(J41<1501,"",J41)
C42: Altitude du terrain (VAC) | F42: =E7 -> 0 | G42: ft | I42: =IF(J41<1501,I41,"altitude max du manuel de vol = 1500 m") -> 0 | N42: =F42-(F40-1013)*28 -> 0
C44: Altitude- | E44: Température | G44: Masse 840 Kg | K44: Masse 640 kg
C45: pression en ft | G45: Piste Béton | I45: Piste Herbe | K45: Piste Béton | M45: Piste Herbe
F46: 0 | G46: =IF($C$47<=$C$86,G80+($C$47-$C$82)*(G84-G80)/($C$86-$C$82),IF($C$47<=$C$90,G84+($C$47-$C$86)*(G88-G84)/($C$90-$C$86),G88+($C$47-$C$90)*(G92-G88)/($C$94-$C$90))) -> 440 | H46: =G46*60/100 -> 264 | I46: =IF($C$47<=$C$86,I80+($C$47-$C$82)*(I84-I80)/($C$86-$C$82),IF($C$47<=$C$90,I84+($C$47-$C$86)*(I88-I84)/($C$90-$C$86),I88+($C$47-$C$90)*(I92-I88)/($C$94-$C$90))) -> 520 | J46: =I46*70/100 -> 364 | K46: =IF($C$47<=$C$86,K80+($C$47-$C$82)*(K84-K80)/($C$86-$C$82),IF($C$47<=$C$90,K84+($C$47-$C$86)*(K88-K84)/($C$90-$C$86),K88+($C$47-$C$90)*(K92-K88)/($C$94-$C$90))) -> 261.61126 | L46: =K46*60/100 -> 156.96676 | M46: =IF($C$47<=$C$86,M80+($C$47-$C$82)*(M84-M80)/($C$86-$C$82),IF($C$47<=$C$90,M84+($C$47-$C$86)*(M88-M84)/($C$90-$C$86),M88+($C$47-$C$90)*(M92-M88)/($C$94-$C$90))) -> 309.17695 | N46: =M46*70/100 -> 216.42386
C47: =IF(J41<1501,IF(F61<841,I41,"#####"),"#####") -> 0 | F47: 15 | G47: =IF($C$47<=$C$86,G81+($C$47-$C$82)*(G85-G81)/($C$86-$C$82),IF($C$47<=$C$90,G85+($C$47-$C$86)*(G89-G85)/($C$90-$C$86),G89+($C$47-$C$90)*(G93-G89)/($C$94-$C$90))) -> 470 | H47: =G47*60/100 -> 282 | I47: =IF($C$47<=$C$86,I81+($C$47-$C$82)*(I85-I81)/($C$86-$C$82),IF($C$47<=$C$90,I85+($C$47-$C$86)*(I89-I85)/($C$90-$C$86),I89+($C$47-$C$90)*(I93-I89)/($C$94-$C$90))) -> 560 | J47: =I47*70/100 -> 392 | K47: =IF($C$47<=$C$86,K81+($C$47-$C$82)*(K85-K81)/($C$86-$C$82),IF($C$47<=$C$90,K85+($C$47-$C$86)*(K89-K85)/($C$90-$C$86),K89+($C$47-$C$90)*(K93-K89)/($C$94-$C$90))) -> 279.4484 | L47: =K47*60/100 -> 167.66904 | M47: =IF($C$47<=$C$86,M81+($C$47-$C$82)*(M85-M81)/($C$86-$C$82),IF($C$47<=$C$90,M85+($C$47-$C$86)*(M89-M85)/($C$90-$C$86),M89+($C$47-$C$90)*(M93-M89)/($C$94-$C$90))) -> 332.95979 | N47: =M47*70/100 -> 233.07185
F48: 30 | G48: =IF($C$47<=$C$86,G82+($C$47-$C$82)*(G86-G82)/($C$86-$C$82),IF($C$47<=$C$90,G86+($C$47-$C$86)*(G90-G86)/($C$90-$C$86),G90+($C$47-$C$90)*(G94-G90)/($C$94-$C$90))) -> 500 | H48: =G48*60/100 -> 300 | I48: =IF($C$47<=$C$86,I82+($C$47-$C$82)*(I86-I82)/($C$86-$C$82),IF($C$47<=$C$90,I86+($C$47-$C$86)*(I90-I86)/($C$90-$C$86),I90+($C$47-$C$90)*(I94-I90)/($C$94-$C$90))) -> 600 | J48: =I48*70/100 -> 420 | K48: =IF($C$47<=$C$86,K82+($C$47-$C$82)*(K86-K82)/($C$86-$C$82),IF($C$47<=$C$90,K86+($C$47-$C$86)*(K90-K86)/($C$90-$C$86),K90+($C$47-$C$90)*(K94-K90)/($C$94-$C$90))) -> 297.28553 | L48: =K48*60/100 -> 178.37132 | M48: =IF($C$47<=$C$86,M82+($C$47-$C$82)*(M86-M82)/($C$86-$C$82),IF($C$47<=$C$90,M86+($C$47-$C$86)*(M90-M86)/($C$90-$C$86),M90+($C$47-$C$90)*(M94-M90)/($C$94-$C$90))) -> 356.74263 | N48: =M48*70/100 -> 249.71984
F49: 45 | G49: =IF($C$47<=$C$86,G83+($C$47-$C$82)*(G87-G83)/($C$86-$C$82),IF($C$47<=$C$90,G87+($C$47-$C$86)*(G91-G87)/($C$90-$C$86),G91+($C$47-$C$90)*(G95-G91)/($C$94-$C$90))) -> 540 | H49: =G49*60/100 -> 324 | I49: =IF($C$47<=$C$86,I83+($C$47-$C$82)*(I87-I83)/($C$86-$C$82),IF($C$47<=$C$90,I87+($C$47-$C$86)*(I91-I87)/($C$90-$C$86),I91+($C$47-$C$90)*(I95-I91)/($C$94-$C$90))) -> 660 | J49: =I49*70/100 -> 462 | K49: =IF($C$47<=$C$86,K83+($C$47-$C$82)*(K87-K83)/($C$86-$C$82),IF($C$47<=$C$90,K87+($C$47-$C$86)*(K91-K87)/($C$90-$C$86),K91+($C$47-$C$90)*(K95-K91)/($C$94-$C$90))) -> 321.06837 | L49: =K49*60/100 -> 192.64102 | M49: =IF($C$47<=$C$86,M83+($C$47-$C$82)*(M87-M83)/($C$86-$C$82),IF($C$47<=$C$90,M87+($C$47-$C$86)*(M91-M87)/($C$90-$C$86),M91+($C$47-$C$90)*(M95-M91)/($C$94-$C$90))) -> 392.4169 | N49: =M49*70/100 -> 274.69183
C51: Température | F51: =E9 -> 0 | G51: °C
F53: =IF(F51<46,F51,"#####") -> 0 | G53: =IF($F$53<$F$47,G46+($F$53-$F$46)*(G47-G46)/($F$47-$F$46),IF($F$53<$F$48,G47+($F$53-$F$47)*(G48-G47)/($F$48-$F$47),G48+($F$53-$F$48)*(G49-G48)/($F$49-$F$48))) -> 440 | H53: =G53*60/100 -> 264 | I53: =IF($F$53<$F$47,I46+($F$53-$F$46)*(I47-I46)/($F$47-$F$46),IF($F$53<$F$48,I47+($F$53-$F$47)*(I48-I47)/($F$48-$F$47),I48+($F$53-$F$48)*(I49-I48)/($F$49-$F$48))) -> 520 | J53: =I53*70/100 -> 364 | K53: =IF($F$53<$F$47,K46+($F$53-$F$46)*(K47-K46)/($F$47-$F$46),IF($F$53<$F$48,K47+($F$53-$F$47)*(K48-K47)/($F$48-$F$47),K48+($F$53-$F$48)*(K49-K48)/($F$49-$F$48))) -> 261.61126 | L53: =K53*60/100 -> 156.96676 | M53: =IF($F$53<$F$47,M46+($F$53-$F$46)*(M47-M46)/($F$47-$F$46),IF($F$53<$F$48,M47+($F$53-$F$47)*(M48-M47)/($F$48-$F$47),M48+($F$53-$F$48)*(M49-M48)/($F$49-$F$48))) -> 309.17695 | N53: =M53*70/100 -> 216.42386
C55: Vent (composante de face) | F55: =E11 -> 0 | G55: kt | H55: → | I55: pour une composante arrière mettre un —
C57: coefficient vent : | F57: =IF(F55>=0,IF(F55<G98,1+(F55)*(J98-1)/(G98-0),IF(F55<G99,J98+(F55-G98)*(J99-J98)/(G99-G98),J99+(F55-G99)*(J100-J99)/(G100-G99))),1+0.1*IF(INT(-F55/2)<>-F55/2,INT(-F55/2+1),INT(-F55/2))) -> 1 | J57: Masse | K57: =F61 -> 734.7 | L57: kg
I58: Piste Béton | K58: Piste Herbe
I59: =I65*F57 -> 346.07833 | J59: =J65*F57 -> 207.647 | K59: =K65*F57 -> 409.00166 | L59: =L65*F57 -> 286.30116
C61: Masse | F61: =E13 -> 734.7 | G61: kg | I61: =IF(F61<=840," ","masse maximale 840 kg dépassée")
C63: masse maximum : | F63: 840 | G63: kg | J63: Masse | K63: =F61 -> 734.7 | L63: kg
...

Sheet Résumé
B1: ='Masse & Centrage'!D44 -> F-BPCT | J1: Limites de Masse & Centrage
B2: Imprimé le : | C2: =NOW() -> 46185.607 | K2: Avion vide | N2: =+'Masse & Centrage'!D5 -> 521.3
K3: CdB | L3: =+'Masse & Centrage'!D6 -> 70 | M3: Copilote | N3: =+'Masse & Centrage'!D7 -> 80
B4: Performances | K4: Passagers AR | L4: =+'Masse & Centrage'!D8 -> 3 | M4: Bagages | N4: =+'Masse & Centrage'!D9 -> 10
K5: ="Essence ("&'Masse & Centrage'!C10&" litres)" -> Essence (110 litres) | L5: ='Masse & Centrage'!C11 -> 0.18333333 | N5: =+'Masse & Centrage'!D10 -> 79.2
C6: Terrain de Départ | E6: Terrain de Destination | G6: Terrain de Dégagement | K6: Total départ | N6: ='Masse & Centrage'!D13 -> 763.5
C7: ='Perfos Départ'!H2 -> LFPN | E7: ='Perfos Destination'!H2 -> LFPZ | G7: ='Perfos Dégagement'!H2 -> 0 | K7: ="Délestage ("&'Masse & Centrage'!C14&" litres)" -> Délestage (40 litres) | L7: ='Masse & Centrage'!C15 -> 0.11666667 | N7: ='Masse & Centrage'!D14 -> -28.8
B8: QNH local | C8: ='Perfos Départ'!E5 -> 1025 | D8: hPa | E8: ='Perfos Destination'!E5 -> 1025 | F8: hPa | G8: ='Perfos Dégagement'!E5 -> 1013 | H8: hPa | K8: Total arrivée | N8: ='Masse & Centrage'!D16 -> 734.7
B9: Altitude terrain | C9: ='Perfos Départ'!E7 -> 538 | D9: ft | E9: ='Perfos Destination'!E7 -> 372 | F9: ft | G9: ='Perfos Dégagement'!E7 -> 0 | H9: ft
B10: Altitude pression | C10: ='Perfos Départ'!N42 -> 202 | D10: ft | E10: ='Perfos Destination'!N42 -> 36 | F10: ft | G10: ='Perfos Dégagement'!N42 -> 0 | H10: ft
B11: Altitude densité | C11: {=+'Perfos Départ'!L8:M8} -> 1330.48 | D11: 0 | E11: {=+'Perfos Destination'!L8:M8} -> 1124.64 | F11: 0 | G11: {=+'Perfos Dégagement'!L8:M8} -> -1800 | H11: 0
B12: Température | C12: ='Perfos Départ'!E9 -> 24 | D12: ° C | E12: ='Perfos Destination'!E9 -> 24 | F12: ° C | G12: ='Perfos Dégagement'!E9 -> 0 | H12: ° C
B13: ISA | C13: =+'Perfos Départ'!G9 -> 9 | E13: =+'Perfos Destination'!G9 -> 9 | G13: =+'Perfos Dégagement'!G9 -> -15
B14: Vent (de face) | C14: ='Perfos Départ'!E11 -> 9 | D14: kt | E14: ='Perfos Destination'!E11 -> 7 | F14: kt | G14: ='Perfos Dégagement'!E11 -> 0 | H14: kt
B15: Masse | C15: ='Perfos Départ'!E13 -> 763.5 | D15: kg | E15: ='Perfos Destination'!E13 -> 734.7 | F15: kg | G15: ='Perfos Dégagement'!E13 -> 734.7 | H15: kg
C17: Décollage | D17: Atterrissage immédiat | E17: Atterrissage | F17: Décollage immédiat | G17: Atterrissage | H17: Décollage immédiat
B18: Piste en dur | C18: ='Perfos Départ'!G19 -> 418.0238 | D18: ='Perfos Départ'!G28 -> 514.866 | E18: ='Perfos Destination'!G19 -> 509.1436 | F18: ='Perfos Destination'!G26 -> 396.40966 | G18: ='Perfos Dégagement'!G19 -> 438.57224 | H18: ='Perfos Dégagement'!G26 -> 397.99008
B19: atterrissage sans volet | D19: ='Perfos Départ'!G29 -> 580.26 | E19: ='Perfos Destination'!G20 -> 572.796 | G19: ='Perfos Dégagement'!G20 -> 480.7464
B20: Piste en herbe | C20: ='Perfos Départ'!G22 -> 503.05754 | D20: ='Perfos Départ'!G28 -> 514.866 | E20: ='Perfos Destination'!G19 -> 509.1436 | F20: ='Perfos Destination'!G29 -> 474.87245 | G20: ='Perfos Dégagement'!G19 -> 438.57224 | H20: ='Perfos Dégagement'!G29 -> 470.35191
B21: atterrissage sans volet | D21: ='Perfos Départ'!G29 -> 580.26 | E21: ='Perfos Destination'!G20 -> 572.796 | G21: ='Perfos Dégagement'!G20 -> 480.7464
C22: Distances avec passage des 15 mètres et majoration Alcyons de 15 %

Sheet MdV DR221 Perfos
B1: extrait du manuel de vol du DR221
C2: Performances de décollage
C3: Distance de passage des 15 mètres au poids de 840 kg ; 1er cran de volets
C4: température en . Zm . °C | E4: 0° | G4: 15° | I4: 30° | K4: 45°
C6: Piste béton
C7: (dont 60 % de roulement)
C9: 0 | D9: =C9*3.2808 -> 0 | E9: 440 | G9: 470 | I9: 500 | K9: 540
C10: 500 | D10: =C10*3.2808 -> 1640.4 | E10: 490 | G10: 540 | I10: 580 | K10: 630
C11: 1000 | D11: =C11*3.2808 -> 3280.8 | E11: 580 | G11: 640 | I11: 700 | K11: 750
C12: 1500 | D12: =C12*3.2808+0.5 -> 4921.7 | E12: 680 | G12: 740 | I12: 800 | K12: 880
C14: Piste herbe
C15: (dont 70 % de roulement)
C17: 0 | D17: =C17*3.2808 -> 0 | E17: 520 | G17: 560 | I17: 600 | K17: 660
C18: 500 | D18: =C18*3.2808 -> 1640.4 | E18: 600 | G18: 660 | I18: 730 | K18: 800
C19: 1000 | D19: =C19*3.2808 -> 3280.8 | E19: 720 | G19: 800 | I19: 870 | K19: 960
C20: 1500 | D20: =C20*3.2808+0.5 -> 4921.7 | E20: 880 | G20: 950 | I20: 1020 | K20: 1160
C22: Pour un poids de décollage inférieur , multiplier par le rapport ( P effectif Kg / 830 ) 2
C25: Performances d'atterrissage
C26: Distance de roulement avec freinage modéré
C27: Masse à l'atterrissage classique (3 points) | I27: 840 | J27: kg | K27: 750 | L27: kg
C28: Vi de présentation (volets 60°) | I28: 120 | J28: km/h | K28: 110 | L28: km/h
C29: Distance de roulement (m), freinage modéré | I29: 250 | J29: mètres | K29: 210 | L29: mètres
C31: Nota : Freiner modérément au centrage AV
